Workbook

Sheet تقييم القادة مايو 2025 - معتمد
A1: Submission ID | B1: Respondent ID | C1: Submitted at | D1: أنا | E1: أود تقييم | F1: مُديري فعّال في توصيل المعلومة والأفكار وإيضاح المهام. | G1: مُديري يحدد الأولويات، ويعيد ترتيب موارد الفريق بانتظام. | H1: مُديري يتخذ قرارات صائبة تصب في مصلحة العمل والفريق. | I1: مُديري يبني ويضع أهداف طموحة وواقعية للقسم والفريق. | J1: هل لديك مرئيات لتطور مديرك حول «الوضوح والأولويات»؟ | K1: مُديري يُمكّن ويحفّز استقلاليتي، وأشعر بثقته العالية بالفريق. | L1: مُديري يحسن في تفويض المهام ومشاركتنا المسؤوليات. | M1: مُديري يقدم يد العون والمشورة في العمل متى ما طلبت منه. | N1: مُديري لديه وعي ذاتي وذكاء عاطفي ويتفهم مشاعر الفريق. | O1: هل لديك مرئيات لتطور مديرك حول «طريقة العمل»؟ | P1: مُديري يؤثر في معنويات الفريق ويحفزني باستمرار. | Q1: مُديري يشجع ويسهل التعاون داخل الفريق. | R1: مُديري يعمل على تعزيز بيئة مشجعة وإيجابية تحت قيادته. | S1: مُديري يُشرك الفريق ويشاورهم عند اتخاذ القرارات. | T1: هل لديك مرئيات لتطور مديرك حول «قيادة الفريق»؟ | U1: مُديري يستثمر وقتاً وجهدًا لتطويري مهنيًا وعمليًا. | V1: مُديري يشاركني مرئيات بناءة تساعدني على التطور. | W1: مُديري يساهم في رفع الأداء والإنتاجية لدى الفريق. | X1: مُديري يشجع ويدعم التفكير الإبداعي والأفكار المختلفة. | Y1: هل لديك مرئيات لتطور مديرك حول «الدعم والتطوير»؟ | Z1: أي شيء آخر تودّ مشاركته مع مديرك؟ | AA1: أي شيء آخر تودّ مشاركته مع الموارد البشرية فقط فيما يخص مديرك؟ | AB1: Untitled checkboxes field | AC1: Untitled checkboxes field (بمجرد الإرسال، سيتم اعتماد تقييمك حول مديرك. هل أنت متأكد؟) | AF1: متوسط التقييم
A2: Np55v5B | B2: oaBlRM | C2: 45741.791 | D2: وديان | E2: أسيل باعبدالله | F2: 4 | G2: 7 | H2: 9 | I2: 6 | J2: الوضع الحالي يحتاج تدخلك كل شوي، وكأننا موظفين عاديين وليسوا مدراء. ساعدينا في اتخاذ القرارات الصحيحة حتى ننطلق بمفردنا، ونتعلم طريقة تفكيرك. | K2: 4 | L2: 4 | M2: 9 | N2: 8 | O2: لا يوجد خطة أو آلية عمل واضحة.. | P2: 6 | Q2: 4 | R2: 3 | S2: 3 | T2: أحيانًا ما نعرف كيف تُتخذ القرارات والتغييرات الداخلية.. وعندما تتم، ما يوصلنا الخبر في الوقت ذاته. | U2: 3 | V2: 7 | W2: 7 | X2: 9 | Y2: مع أننا ما نجلس إلا نادرًا، لكن يعجبني أسلوبك في مشاركة المرئيات، وأفكارك، وأتحمس جدًا بعد كل جلسة معك. كثري منها. | AA2: لا يوجد | AB2: بمجرد الإرسال، سيتم اعتماد تقييمك حول مديرك. هل أنت متأكد؟ | AC2: TRUE | AF2: =AVERAGE(U2:X2,P2:S2,K2:N2,F2:I2) -> 5.8125
A3: 81ooYJk | B3: v0oJyX | C3: 45769.485 | D3: أنس الأهدل | E3: أسيل باعبدالله | F3: 8 | G3: 7 | H3: 10 | I3: 6 | J3: دايمًا ألاحظك تركزي عالطوارئ والهام والعاجل، وتسحبي عالهام وغير العاجل. مثلًا، واضح أن التواصل كان يحتاج بناء فريق، كتّاب تحديدًا. بينما معظم تركيزك كان عالعمليات اليومية وحملات الإطلاق وإطفاء الحرائق. | K3: 7 | L3: 6 | M3: 10 | N3: 9 | O3: أحب الشغل معك، وعادة ننجز، لكن اللي يضاقني أنه إنجاز بعفوية وعشوائية. بدون آلية عمل مستدامة لا تعتمد على تدخل أسيل وتواجدها الدائم. كثير أحيان أحس أننا في 2018. | P3: 8 | Q3: 8 | R3: 6 | S3: 10 | T3: فيه ثغرة في التواصل الداخلي واتخاذ القرارات داخل الفريق. أؤمن أن كل قرار تتخذيه لسبب. نتمنى فقط مشاركتنا أو مشورتنا قبل اتخاذ القرارات الكبيرة، خاصة بما يؤثر فريقنا. | U3: 3 | V3: 7 | W3: 7 | X3: 10 | Y3: تعجبني صراحتك وكرمك في المرئيات. ما تخبي شيء إيجابي أو سلبي. | AB3: بمجرد الإرسال، سيتم اعتماد تقييمك حول مديرك. هل أنت متأكد؟ | AC3: TRUE | AF3: =AVERAGE(U3:X3,P3:S3,K3:N3,F3:I3) -> 7.625
A4: jaDD456 | B4: 70KZy2 | C4: 45777.412 | D4: مشاري الحمود | E4: أسيل باعبدالله | F4: 7 | G4: 8 | H4: 10 | I4: 7 | J4: أسيل لديها قدرة في اقتراح ترتيب جديد للفريق بين المشاريع، دائمًا أرجع ولا أستغني عن رأيك. أظن أننا جميعًا تطورنا خلال الفترة الماضية في التواصل وشرح التحديثات، وأقدر هذا جدًا. بخصوص أهداف الفريق أحيانًا جميعنا يجرفنا الحماس للمشاريع الجديدة الرائعة وننسى مواردنا وقدرات الفريق وعامل الوقت، أنا متهم بهذه أيضًا. | K4: 8 | L4: 6 | M4: 9 | N4: 8 | O4: الفترة الماضية من أفضل فتراتنا في العمل من ناحية التفويض والثقة، وأقدر هذا جدًا. أحيانًا نغرق في وسط المهام ولا نجد الوقت الكافي للاستشارة، ولكن الأمور جيدة بشكل عام. كثير من نقاشاتنا بخصوص الفريق تتعلق بالموظفين الذي يمرون فترات سيئة، أحاول دائمًا تقديم الرحمة على القسوة، ومحاولة التطوير والخروج من الفترة السيئة، وفي الفترة الأخيرة للأمانة أرى تعاون عالي منك، وأشكرك على ذلك. | P4: 9 | Q4: 9 | R4: 7 | S4: 8 | T4: لا أحد يستشير فريقه عن القرارات الكبيرة أكثر منك أسيل، وأشكرك على هذا. الفريق «الموظفين الذين لا تتقاطعين معهم» ينظر لك بإكبار ويحب العمل معك، ولكن طبيعي مع انشغالاتك تقل التداخلات، ولكن حضورك معهم يسعدهم. | U4: 7 | V4: 6 | W4: 9 | X4: 10 | Y4: أتمنى لو أسمع منك مرئيات أكثر، في حال وجودها. أنتِ من أفضل من يعطي مرئيات، وتتعاطفي معنا، لكن هذا لو جلسنا. ونادرًا ما نجلس. استثمري أكثر في الجلوس مع الفريق ومشاركة المرئيات.. ليس مجرد متابعة مهام. | Z4: مدري وشلون أقولها، ولكن خلينا نروح لمنطقة أبعد، أدري الموضوع عن رئيس الشركة هههه بس خلونا نكبر خلاص ختمنا مرحلة الشركة الصغيرة. | AB4: بمجرد الإرسال، سيتم اعتماد تقييمك حول مديرك. هل أنت متأكد؟ | AC4: TRUE | AF4: =AVERAGE(U4:X4,P4:S4,K4:N4,F4:I4) -> 8
A5: QK22Zvk | B5: ReoEjp | C5: 45777.582 | D5: ميسم | E5: أسيل باعبدالله | F5: 8 | G5: 7 | H5: 8 | I5: 6 | J5: كل شيء فُل ويحمّس! لكن أولويات المشاريع ما تُبنى بشكل فعّال، كثير من الأحيان تكون بشكل مفاجئ بحسب رغبة لحظية، زي «خلونا نلحق نسويه قبل رمضان، وباقي على رمضان أسبوع» هههه احنا فريق رهيب نقدر نتشكّل بسرعة وننفذ، لكن هذا مب صحي إذا نبغى برامجنا الرهيبة تكبر وتكثر، وأخذت وقتها الكافي في بناء المحتوى. ماذا لو قدرنا نلتزم بخطة الربع ونقفلها بالشمع الأحمر على قولتك. وأي شيء جديد ننقله مباشرة للربع الجاي؟ بيساعد في ضبط التوقعات عند فريق المالية، والإنتاج، والأعمال، والنشر. | K5: 6 | L5: 7 | M5: 10 | N5: 9 | O5: الله يسدد خطاها ويعينها. ودي لو تنفتح أسيل على الثقة بباقي الفريق وتصير تفوّض مهام أكثر، أحيان مو صح يشعر الفريق ان فيه ناس مُفضلّين عن غيرهم. + المُفضلين يشيلون أكثر من ما ينبغي لأن أسيل ما تثق إلا فيهم بالتالي حتى مافيه فايدة من التوظيف إذا كنت بسوي كل شيء في النهاية. هههه | P5: 7 | Q5: 7 | R5: 7 | S5: 7 | T5: في كثير من الأحيان يشعر الفريق تحت التهديد للتنفيذ، أو انهم ما راح يحصلوا على رضى وكلمة حلوة من الادارة إلا لو عملوا 24 ساعة بدون اجازة نهاية أسبوع، أو حتى اجازات سنوية، وهذا يعزز القلق وغير صحي. ما أعرف وش التصرف الصحيح بالضبط لكن أعتقد لو أشعرنا الفريق بان القيادة في صفكم دائمًا، راح نقدر نحافظ على نفسيات حلوة تعمل بحُب، وتاخذ أيام الراحة والاجازات بدون خوف من فكرة انها «خذلت الادارة». + إنتاجاتنا أكثر من الفريق القائم عليها، أعتقد مفترض نستوعب هالشيء قبل ما نقول ان فيه أحد مقصّر. | U5: 5 | V5: 5 | W5: 8 | X5: 10 | Y5: احنا في عجلة نركض طوال السنة، يصعب أحيان كثيرة وجود أيام بصفاء ذهني يساعد على حضور برنامج يطوّر من مهاراتي. + المرئيات أكثرها عن انجاز الإنتاجات من عدمها، ودي لو مره نجلس ويكون فيه مرئيات واضحة على مهاراتي في العمل، تخليني أنتبه للسلبيات وأتعلّم منك وش ممكن يطوّرها. | AB5: بمجرد الإرسال، سيتم اعتماد تقييمك حول مديرك. هل أنت متأكد؟ | AC5: TRUE | AF5: =AVERAGE(U5:X5,P5:S5,K5:N5,F5:I5) -> 7.3125
A6: 44XXZ8d | B6: PerexQ | C6: 45736.799 | D6: سيف | E6: أنس الأهدل | F6: 7 | G6: 9 | H6: 8 | I6: 8 | J6: لا | K6: 9 | L6: 9 | M6: 7 | N6: 7 | O6: لا | P6: 7 | Q6: 8 | R6: 7 | S6: 6 | T6: لا | U6: 7 | V6: 7 | W6: 6 | X6: 10 | Y6: لا | Z6: نحبك، ونعلم دائما أنك أفضل مدير ممكن يتمودر علينا، صالح مصطلح يتمودر؟ والله ماهو صالح | AA6: لا | AB6: بمجرد الإرسال، سيتم اعتماد تقييمك حول مديرك. هل أنت متأكد؟ | AC6: TRUE | AF6: =AVERAGE(U6:X6,P6:S6,K6:N6,F6:I6) -> 7.625
A7: 1APvyOW | B7: Qar8O8 | C7: 45741.794 | D7: نوره الرشيد | E7: أنس الأهدل | F7: 8 | G7: 5 | H7: 8 | I7: 8 | J7: لا يوجد | K7: 10 | L7: 10 | M7: 10 | N7: 10 | O7: لا يوجد | P7: 6 | Q7: 10 | R7: 7 | S7: 10 | T7: لا يوجد | U7: 6 | V7: 6 | W7: 4 | X7: 10 | Y7: لا يوجد | Z7: ما يجي ببالي شيء معين، إلا شكرًا لدعمك المستمر. | AA7: ما يجي ببالي إلا أني أظنه من أفضل المدراء في ثمانية، بس أحيانًا تحسه بعيد عن الفريق لكن ما نقصّر وننشب له. 👍 | AB7: بمجرد الإرسال، سيتم اعتماد تقييمك حول مديرك. هل أنت متأكد؟ | AC7: TRUE | AF7: =AVERAGE(U7:X7,P7:S7,K7:N7,F7:I7) -> 8
A8: yPZqa7p | B8: WX1Xbv | C8: 45755.593 | D8: سيف | E8: أنس الأهدل | F8: 8 | G8: 8 | H8: 9 | I8: 7 | J8: مديري يجيد ترتيب أولويات المهام والوقت من يوم يومه، فما ألاحظ تحسن لأنو ما عندي تعقيب على هاذ الشي من قبل | K8: 7 | L8: 9 | M8: 8 | N8: 7 | O8: لالا | P8: 8 | Q8: 10 | R8: 9 | S8: 6 | T8: ... | U8: 7 | V8: 8 | X8: 10 | Y8: دائما يحاول أنس أنو يقدملك منصات تساعدك في شغلك، مرئيات، كورسات... إلخ | Z8: لا والله... | AA8: لو يبقى أنس مديري، توقعوا مني راح صير مكان أبو مالح يوما ما | AB8: بمجرد الإرسال، سيتم اعتماد تقييمك حول مديرك. هل أنت متأكد؟ | AC8: TRUE | AF8: =AVERAGE(U8:X8,P8:S8,K8:N8,F8:I8) -> 8.0666667
A9: 44XOZQA | B9: GVxbDz | C9: 45762.658 | D9: نورة السبيعي | E9: أنس الأهدل | F9: =AVERAGE(F10:F14) -> 7 | G9: =AVERAGE(G10:G14) -> 6.4 | H9: =AVERAGE(H10:H14) -> 9 | I9: =AVERAGE(I10:I14) -> 7.4 | J9: تكّة وضوح بس وتصير الدنيا وردية. | K9: =AVERAGE(K10:K14) -> 9.2 | L9: =AVERAGE(L10:L14) -> 9.6 | M9: =AVERAGE(M10:M14) -> 9.2 | N9: =AVERAGE(N10:N14) -> 8.6 | O9: لا، ممتازة. | P9: =AVERAGE(P10:P14) -> 6.2 | Q9: =AVERAGE(Q10:Q14) -> 6.6 | R9: =AVERAGE(R10:R14) -> 7.4 | S9: =AVERAGE(S10:S14) -> 7 | T9: لا. | U9: =AVERAGE(U10:U14) -> 6.4 | V9: =AVERAGE(V10:V14) -> 7 | W9: =AVERAGE(W10:W14) -> 7 | X9: =AVERAGE(X10:X14) -> 9.8 | Y9: بس لو يشاركنا مرئيات أكثر حول عملنا، ويساعدنا على التطوير المستمر. | Z9: ما عندي ملاحظات، رائع أنس في الدعم وفتح المساحة، ودائم لما أحتاج شيء وأرجع له ما يقصر أبدًا فحتى لو عندي ملاحظات سهل جدًا أقولها له في وقتها فالتواصل معه سهل. لكن ودّي بمرئيات أكثر حول العمل والتطوير المستمر. | AB9: بمجرد الإرسال، سيتم اعتماد تقييمك حول مديرك. هل أنت متأكد؟ | AC9: TRUE | AF9: =AVERAGE(U9:X9,P9:S9,K9:N9,F9:I9) -> 7.7375
A10: aQNyjMW | B10: rbd0eo | C10: 45742.75 | D10: شهد باعبدالله | E10: أنس الأهدل | F10: 5 | G10: 5 | H10: 10 | I10: 10 | J10: الأولويات وإيضاح المهام تصل دائمًا بعد الطلب، بالنسبة لي. كثير مرات أتمنى لو تذكر هذه الأمور من طرفك، وهو مو من إهمال قد ما أنك تعرف وتعّي بأني متابعة وأعرف المطلوب مني، مثلًا. ولكن الكلام مجانًا، والبخل في الوضوح والحديث ليس من سمات الناس الكويسة. (مع كل الحب — والتفهم جدًا) | K10: 10 | L10: 10 | M10: 10 | N10: 10 | O10: خيرٌ من ألف مدير. لو توظفت خمس مرات، بطلبهم بكل مرة يخلونه مديري. 😁 كل النقاط اللي ذكرت فوق، أنس أفضل من يقدّمها لفريقه. وأعتقد بأن الذكي كفايه بيستغلها وبينطلق. هذا و الله أعلم. فأنا ممتنة أشدّ الامتنان على كل هذا. | P10: 8 | Q10: 5 | R10: 10 | S10: 10 | T10: ما عليه كلام. | U10: 6 | V10: 7 | W10: 10 | X10: 10 | Y10: ما عليه كلام، من جد. | Z10: ما قد شفت منك إلّا كل ما هو خير. وفي كل مرة، أتأكد بأن كل الأزمات العالمية حول المدير، هي كذبة وأنس أبطلها واحدة واحدة. وأي تعليق أو تقييم حول الأداء أو كل الأسئلة اللي ذكرت فوق هي مرئيات عابرة، ولا تأثر على سيّر العمل، وأمور قابل للنقاش عنها دومًا ومشاركتها معك.. وتتقبّلها وتتعدل، عادي. فأنا متأكدة بأن كل نموذج مميز في الفريق وصار غير قابل للتخلي عنه لاحقًا في الشركة لأن عليه لمسات قيادتك. —> نوادر ثمانية. وصلنا السنة الثالثة، وأعي جيّدًا بكل مرة بأن المرحلة اللي بعدها بندخل خط يحمسني للعمل فيه معك أكثر، ولا أتمنى بأن يتوقف هذا الشغف. — ومع الجزئية الرابعة في المرئيات. صار لازم أذكر حقيقة بأن أعتقد بأن الأمور الوظيفية الشخصية فعلًا مفقودة وغائبة عن الظهور. ولا أشوف بأن فيه تعزيز لأي قيادة داخلية في الفريق رغم أنها بسيطة وتقدر تُبنى خصوصًا مع زيادة الأعداد، وبتزيد أكثر. حتى الترقية، وتغيير المسمى الوظيفي - كما هو مستحق - ما حصل. وأرى من غير العدل بأن أتساوّى مستوى مع أشخاص توهم توظفوا، ومطلوب مني أشرف عليهم خلال مدة عملهم. أعي بأن صلاحياتي بالعمل تزيد، وهذا كرمًا منك، ولكن المسار المهني مضروب وباقي كما هو وما اختلف شيء. المسمى مفقود، القيادة مفقودة، الترقية مفقودة، المستحق طالبت فيه وأخذته بشقّ الأنفاس وهو مجرد تصحيح للصمت اللي حصل وما تم تداركه. وأنا أرى بأن كل هذا له قيمة عالية جدًا، والكلام عنه مزعج لأن مفترض يكون تلقائي. | AA10: لا تخلونه يروح مكان مهما يكن. لمصلحة الشركة صدقوني. | AB10: بمجرد الإرسال، سيتم اعتماد تقييمك حول مديرك. هل أنت متأكد؟ | AC10: TRUE | AF10: =AVERAGE(U10:X10,P10:S10,K10:N10,F10:I10) -> 8.5
A11: RGKeZNJ | B11: vVODdd | C11: 45753.421 | D11: عمر خطاب | E11: أنس الأهدل | F11: 7 | G11: 8 | H11: 10 | I11: 8 | J11: أشوف الأمور جيدة جدًا في هذه الناحية، يعطيك ألف عافية. أحيانًا بعض المهام الجديدة بطبيعتها قد تحتاج توضيح أكثر في البداية. ونعاني في الأولويات وأوقات تسليم المهام أحيانًا عشان نأخذ مهام من فرق أخرى جديدة ومستعجلة، أحيانًا كثيرة بشكل يومي. | K11: 10 | L11: 10 | M11: 10 | N11: 10 | O11: هذه من أحلى الحاجات في ثقافة الشركة وفريقنا. أثمّن الثقة والاستقلالية بشكل دائم، وما عندي أي ملاحظات. | P11: 7 | Q11: 10 | R11: 10 | S11: 10 | T11: بالمجمل الأمور طيبة هنا. ربما بكون ممتاز لو أقدر أسمع بين فترة وثانية رأيك\انطباعات\أفكار\اقتراحات عن المهام التي نعمل عليها، حاجات نفكّر فيها أكثر للمستقبل القريب.. إلخ | U11: 7 | V11: 9 | W11: 9 | X11: 10 | Y11: ما عندي ملاحظات مفصّلة هنا، لكن لو في البال أي مساحات معينة تشوف نحتاج نستثمر فيها وقت أكثر من ناحية البحث أو التعلم، أو حاجات رح نتعلمها في المستقبل بكون رائع | Z11: يعطيك ألف عافية أنس. متحمس للفترات القادمة، والأمور طيّبة. لخّصت أبرز الحاجات اللي ببالي في النقاط أعلاه. زبدتها: - بعض المهام الجديدة ممكن بحتاج فيها توضيح أكثر. - أحيانا نعاني من مهام مستعجلة ومفاجئة من فرق أخرى وتأخر المهام المرتبطة بفريقنا.. وأحيانًا بشكل كبير. جاءت فترة جيدة هذا الربع يكون عندي مهمة جديدة ومستعجلة يوميًا تقريبًا، وهذا شوي يكون مرهق في ترتيب أولويات مهامي - أحب أعرف بين فترة وثانية لو في بالبال أي ملاحظات أو اقتراحات أو أفكار عن مخرجات المهام وكذا. شكرًا جزيلًا يا أنس مرة أخرى، ويعطيك العافية يا رب. | AB11: بمجرد الإرسال، سيتم اعتماد تقييمك حول مديرك. هل أنت متأكد؟ | AC11: TRUE | AF11: =AVERAGE(U11:X11,P11:S11,K11:N11,F11:I11) -> 9.0625
A12: VLEWK7j | B12: LE8QVG | C12: 45740.504 | D12: فيصل | E12: عبدالرحمن أبومالح | F12: 8 | G12: 5 | H12: 8 | I12: 6 | J12: - | K12: 8 | L12: 10 | M12: 8 | N12: 8 | O12: - | P12: 5 | Q12: 3 | R12: 3 | S12: 3 | T12: - | U12: 8 | V12: 3 | W12: 3 | X12: 10 | Y12: - | AB12: بمجرد الإرسال، سيتم اعتماد تقييمك حول مديرك. هل أنت متأكد؟ | AC12: TRUE | AF12: =AVERAGE(U12:X12,P12:S12,K12:N12,F12:I12) -> 6.1875
A13: WO9a4NL | B13: 5lJ7oM | C13: 45769.491 | D13: معاذ الحربي | E13: عبدالرحمن أبومالح | F13: 7 | G13: 7 | H13: 8 | I13: 5 | J13: العمل معك بالغالب مريح وواضح. الشي الوحيد اللي أشوف ممكن يضيف فرق، هو لو تشاركنا أكثر بالصورة الكبيرة والخطط طويلة المدى، عشان نحس إننا ماشين سوا على نفس الطريق ونكون جزء من الرؤية بشكل أكبر. | K13: 10 | L13: 10 | M13: 10 | N13: 6 | O13: متواجد وقت ما نحتاجك دائمًا، وما تقصّر أبدًا في الدعم والمشورة. وبرغم إن عندك وعي وذكاء عاطفي ممتازين، أحيانًا أحس إنك تكون مندفع وما تاخذ برأي أحد غيرك. لو صار فيه تواصل أعمق بهالجانب، أتوقع راح ينعكس بشكل كبير وإيجابي على الفريق. | P13: 6 | Q13: 8 | R13: 7 | S13: 6 | T13: أقدّر حرصك على خلق بيئة إيجابية ومشجعة داخل الفريق، ودائمًا تبذل جهد في تعزيز التعاون بيننا. لكن أحس إن فيه مساحة لتأثير أكبر على معنويات الفريق، خصوصًا في أوقات الضغط أو التحديات. وبالنسبة لموضوع المشاركة في اتخاذ القرار، أحيانًا أحس إنك تمشي بسرعة قبل ما تستشير الفريق بشكل كافٍ، وأشوف إن وجود مساحة أوسع للنقاش ممكن يطلع بقرارات أقوى، ويزيد شعور الفريق بالشراكة والمسؤولية. | U13: 5 | V13: 8 | W13: 6 | X13: 10 | Y13: مشاركتك المرئيات ممتاز ودايم تفتح مساحة للنقاش، وهذا ساعدني كثير إني أتطوّر وأشتغل بثقة أفضل. بس أحيانًا أحس إن سرعة العمل تخليك ما تركز على تطوير كل فرد بنفس المستوى أو ما تتابع معنا بشكل شخصي كفاية. يمكن لو كان فيه وقت مخصص للتوجيه الفردي بيكون له أثر كبير على تطوّر الفريق ككل، خصوصًا في فترات الركود أو التكرار. | AB13: بمجرد الإرسال، سيتم اعتماد تقييمك حول مديرك. هل أنت متأكد؟ | AC13: TRUE | AF13: =AVERAGE(U13:X13,P13:S13,K13:N13,F13:I13) -> 7.4375
A14: 0QrRrrj | B14: OjbpoR | C14: 45761.193 | D14: البراء | E14: عبدالرحمن أبومالح | F14: 8 | G14: 7 | H14: 9 | I14: 8 | J14: الأمور تمام والتواصل معك دائمًا واضح، أرجوا فقط أن يكون هناك موائمة دائمة بالأولويات. | K14: 8 | L14: 8 | M14: 8 | N14: 9 | O14: لا توجد ملاحظات، طريقة العمل بيننا رائعة وأشعر أن لدي كل الثقة والاستقلالية. | P14: 5 | Q14: 7 | R14: 7 | S14: 6 | T14: لا نطالب أبدًا بالتسليك والتلميع في غير محله، لكن التشجيع والثناء عندما تضبط الأمور لها وقع كبير على الفريق، وخصوصًا القادة. والعكس صحيح، فالنقد أمام الملأ فيه من تظبيط المعنويات ما ينقلب ضد نفعية النقد. | U14: 6 | V14: 8 | W14: 7 | X14: 9 | Y14: سبق وشاركتني عدة مرئيات مفيدة وفي محلها! لكن قطعًا هناك مساحة لإحراز نجاحات أكبر في دعم وتطوير الرؤساء والقادة مهنيًا وعمليًا. سأشارك بعض الأفكار والقرارات المقترحة معك في اجتماعنا القادم. | AB14: بمجرد الإرسال، سيتم اعتماد تقييمك حول مديرك. هل أنت متأكد؟ | AC14: TRUE | AF14: =AVERAGE(U14:X14,P14:S14,K14:N14,F14:I14) -> 7.5
A15: pbxpxrq | B15: ajV76E | C15: 45768.63 | D15: أسيل | E15: عبدالرحمن أبومالح | F15: 8 | G15: 6 | H15: 10 | I15: 8 | J15: مبدئيًا أنا أعترض على التقييم المستمر للمدراء، قبل أقل من سنة سوّينا نفس التقييم، ليش نتخيّل أنّه يحتاج يرجع يسمع كل شيء من جديد؟ ما أفهم. عمومًا، أزمة الأولويات هي أزمة عامّة ومتوقعة لأي شركة ناشئة، أو لأي شركة مسرعة. فما عادت لخبطة الأولويات تؤثّر فيني، ممكن تؤثر في الفريق التقني أكثر. في الإنتاج صارت أقل حدّة، بس ممكن المشكلة أننا نحدد الأولويات، ونتوقع أنّها تنتهي في أسبوعين، بالرغم من أنّها عملية تحتاج أشهر أو أسابيع حتّى تبان نتائجها. غير أن كل شيء أولوية، يجعل من كل شيء متعطّل. ما أظن أني أتوقع من عبدالرحمن شيء، إلا الصبر والثقة في أن الأولويات ستجد طريقها لتكون واقعًا، وأن تفعيل مود الطوارئ والغضب باستمرار، يجعل كل شيء يخلّص عشان نهدئ المدير، أكثر من أنّه الصح الذي يجب أن يكون. | K15: 8 | L15: 10 | M15: 8 | N15: 5 | O15: آخر سؤال فخ، لو ما حطّوه أحسن. | P15: 7 | Q15: 7 | R15: 7 | S15: 7 | T15: أشعر أن فريق الإنتاج الأقل حظًّا في تشجيع عبدالرحمن، يمكن لأنه أقدم الفرق، أو الأكثر حظًّا بالتقدير من الجمهور. بس، أظن وجود تعليقات داعمّة يمنةَ ويسرة لفريق الإنتاج أمام الآخرين، بتكون لفتة لطيفة. أحب مناوشاته مع فريق المحتوى باستمرار، بس أحيانًا أشعر أنّهم يخافون منها ههههه أفهم أنّهم مفترض ما يخافون، لكن ممكن لو نشارك المدح، بحيث يصير الانتقاد أخف وطأة. | U15: 6 | V15: 8 | W15: 8 | X15: 10 | Y15: قلتها سابقًا، صعبة عبدالرحمن يفكّر في الدعم والتطوير، لأننا كبار وكذا. لكن، ممكن تكون في فتح الفرص والآفاق للتنفيذيين. وجودي في اجتماعات مهمّة وحساسة في مستقبل الشركة، أكيد أنّه جزء من تطويري، وسبق وناقشتها مع الريّس. خلق طرق تفكير جديدة، أو اقتراح برامج محتوى جديدة ... إلخ كلها أشياء داعمة، ويسوّيها عبدالرحمن باستمرار، ما يقصّر. | AB15: بمجرد الإرسال، سيتم اعتماد تقييمك حول مديرك. هل أنت متأكد؟ | AC15: TRUE | AF15: =AVERAGE(U15:X15,P15:S15,K15:N15,F15:I15) -> 7.6875
A16: xXx5MN9 | B16: XvEqpj | C16: 45742.381 | D16: علي بوصالح | E16: عبدالرحمن أبومالح | F16: 7 | G16: 8 | H16: 10 | I16: 8 | J16: - مديري كان لديه مشكلة في الوضوح، لكن في الفترة الأخيرة تحسّن. - الأولويات تتغير كثير وأشوفها مشكلة. | K16: 9 | L16: 10 | M16: 9 | N16: 8 | O16: - مُمكّن رائع. ما أذكر يوم من الأيام حسّيت إنّي عندي عوائق في اتخاذ القرارات. - في تحدّي لمن يبدأ يتدخّل في التفاصيل الصغيرة، لأنه أحيانًا هو ما هو داخل كفاية معانا في عملية التطوير. فالمفترض إذا قلنا رأي مُخالف له علاقة بآلية العمل يسمع لنا. - أحيانًا يزعل من الفريق ويبدأ يتصرّف بشكل قد ينفر الموظفين. | P16: 9 | Q16: 8 | R16: 9 | S16: 8 | T16: - ما يتدخّل كثير بيني وبين أعضاء الفريق الآخرين، وأشوفه شيء جيّد لأن كلّنا خبرتنا كبيرة فالمفترض نتعامل مع بعضنا البعض ونخلص المواضيع. - الموضوع فيه أريحية كبيرة في التعامل. | U16: 9 | V16: 8 | W16: 10 | X16: 10 | Y16: - أكثر المرئيات تكون على المهارات الإدارية وأتوقع هنا دوره الأكبر يكون. | Z16: أبد، عساك على القوّة. | AA16: لا يوجد شيء. | AB16: بمجرد الإرسال، سيتم اعتماد تقييمك حول مديرك. هل أنت متأكد؟ | AC16: TRUE | AF16: =AVERAGE(U16:X16,P16:S16,K16:N16,F16:I16) -> 8.75
A17: RGKy1KP | B17: yrE0N8 | C17: 45753.505 | D17: زياد السرور | E17: عبدالله الغامدي | F17: 5 | G17: 3 | H17: 8 | I17: 6 | J17: عدم وضوح بالأولويات والأهداف، وتغيرات مفاجئه تسبب عدم أريحية بالوضع | K17: 4 | L17: 4 | M17: 10 | N17: 6 | O17: مشاريع يُتخذ فيها قرار دون علم مدير المشروع. وهذا مربك قليلا. | P17: 6 | Q17: 5 | R17: 6 | S17: 8 | T17: اجعلها سهلة بالتواصل، ولا تكون مركزية للبعد عن المشاحنات والتنافس الضار. | U17: 5 | V17: 10 | W17: 5 | X17: 5 | Y17: البعد عن المركزية، والاستماع الفعال للكل بتنوع مرئياتهم واقتراحاتهم وتجربتها | Z17: فوض وراقب، ولا تفوض وتراقب وتدخل في النهايات بأسئلة تبعث الريبة بالعمل كاملا الاسلوب الجميل الواضح منهجك، ونريده اكثر بالمهام يطلب التحديث اذا لا يوجد بتاتا التحديثات لا تطلب يوميا لانها تعتمد على أطراف أخرى تقسيم المنتجات والبيع لها وطلبات الفريق امنيتي ان تؤخذ بعين الاعتبار على ما بها من اعتبار | AA17: أسلوبي واضح أريد تغيير بعض الشيء لما يناسب. - أمنيتي الوضوح بين عبدالله وفيصل لأنه يسبب إرباك غير مريح. ملاحظاتي للتحسين، وعبدالله جدًا ممتاز ، ولكن التحسين مطلب. | AB17: بمجرد الإرسال، سيتم اعتماد تقييمك حول مديرك. هل أنت متأكد؟ | AC17: TRUE | AF17: =AVERAGE(U17:X17,P17:S17,K17:N17,F17:I17) -> 6
A18: Bz4RevN | B18: e899yx | C18: 45754.507 | D18: بندر العاصمي | E18: عبدالله الغامدي | F18: 7 | G18: 6 | H18: 9 | I18: 8 | J18: لايوجد | K18: 6 | L18: 7 | M18: 10 | N18: 8 | O18: لايوجد | P18: 8 | Q18: 8 | R18: 8 | S18: 8 | T18: لايوجد | U18: 7 | V18: 9 | W18: 8 | X18: 7 | Y18: لايوجد | AB18: بمجرد الإرسال، سيتم اعتماد تقييمك حول مديرك. هل أنت متأكد؟ | AC18: TRUE | AF18: =AVERAGE(U18:X18,P18:S18,K18:N18,F18:I18) -> 7.75
A19: 1APeW2p | B19: DEabvp | C19: 45743.944 | D19: أميرة | E19: عبدالله الغامدي | F19: 8 | G19: 6 | H19: 10 | I19: 9 | J19: بعض القرارات تُتخذ بدون توضيح كافي للآلية، الوضع الحالي ممتاز. لكن دائما نستطيع تحسينه. | K19: 10 | L19: 8 | M19: 10 | N19: 10 | O19: ياريت فيه وضوح أكثر بين عبدالله وفيصل لأن هذا الشيء يشتت. | P19: 10 | Q19: 10 | R19: 10 | S19: 8 | T19: فوض المهام بيسر، استمع للأراء بإنصات، دون تهكّم | U19: 6 | V19: 10 | W19: 10 | X19: 7 | Y19: عبدالله جدًا ممتاز .. ملاحظاتي للتحسين فقط. | Z19: طبيعة عملنا المتغيرة، تحتاج توجيه مستمر، وذكاء عاطفي عالي ووجود 3 موظفين جدد تطلب بالفترة الاخيرة مجهود وادارة جيدة وعبدالله كان مرن في ذلك. فيشكر عليه فعلًا. | AA19: شكرا على احسانكم، والتأكد من سماع صوت كل فرد في ثمانية | AB19: بمجرد الإرسال، سيتم اعتماد تقييمك حول مديرك. هل أنت متأكد؟ | AC19: TRUE | AF19: =AVERAGE(U19:X19,P19:S19,K19:N19,F19:I19) -> 8.875
A20: XxlaOjL | B20: 2zOODg | C20: 45754.507 | D20: الصوفي | E20: عبدالوهاب محمد | F20: 10 | G20: 10 | H20: 10 | I20: 8 | J20: اهم شي تستمر على ما انت عليه وتسمع اكثر | K20: 10 | L20: 10 | M20: 8 | N20: 8 | O20: الحلو انك قريب من الفريق بشكل ممتاز | P20: 8 | Q20: 8 | R20: 9 | S20: 7 | T20: لا يوجد | U20: 10 | V20: 10 | W20: 10 | X20: 10 | Y20: استمر | AB20: بمجرد الإرسال، سيتم اعتماد تقييمك حول مديرك. هل أنت متأكد؟ | AC20: TRUE | AF20: =AVERAGE(U20:X20,P20:S20,K20:N20,F20:I20) -> 9.125
A21: eqZVBLO | B21: BqMoXA | C21: 45761.52 | D21: أحمد سالم | E21: عبدالوهاب محمد | F21: 8 | G21: 10 | H21: 9 | I21: 10 | J21: الوضوح يخلي العمل مريح حتى مع وجود الضغط، لا توجد لدي مرئيات، استمر بنفس الأسلوب. | K21: 10 | L21: 10 | M21: 10 | N21: 10 | O21: طريقة العمل مناسبة بالنسبة لي. | P21: 10 | Q21: 10 | R21: 8 | S21: 8 | T21: يعجبني ثناؤه وتشجيعه لكل أفراد الفريق. | U21: 8 | V21: 9 | W21: 9 | X21: 8 | Y21: يعجبني مشاركة مرئياتك مع نهاية كل مشروع، استمر بهذا. | Z21: لا توجد. | AA21: لا تعطوه مسؤولية قسم زيادة فوق المصورين والملونين والتخزين هههههه سيبولنا شوي منه، ما نبغاه يتشتت. | AB21: بمجرد الإرسال، سيتم اعتماد تقييمك حول مديرك. هل أنت متأكد؟ | AC21: TRUE | AF21: =AVERAGE(U21:X21,P21:S21,K21:N21,F21:I21) -> 9.1875
B22: elz87k | C22: 45736.805 | D22: ياسر | E22: عبدالوهاب محمد | F22: 9 | G22: 10 | H22: 10 | I22: 10 | J22: اتمنى يستمر اكثر ، ونكثر اجتماعاتنا لكي نصل الى توافق اكثر. ولانشعر بالقلق من ترتيب أولوياتنا. | K22: 10 | L22: 10 | M22: 10 | N22: 10 | O22: لايوجد ، وودي ياحب انك تقلل الظغط على نفسك. | P22: 10 | Q22: 10 | R22: 9 | S22: 10 | T22: لا واستمر في ذالك، | U22: 8 | V22: 10 | W22: 9 | X22: 10 | Y22: لايوجد | Z22: احترم فيك التشجيع للفريق ، واحترم فيك انك تاتي لنا كل فترة وتناقشنا في الاغلاط وايضاً في الايجابيات. | AA22: لايوجد. | AB22: بمجرد الإرسال، سيتم اعتماد تقييمك حول مديرك. هل أنت متأكد؟ | AC22: TRUE | AF22: =AVERAGE(U22:X22,P22:S22,K22:N22,F22:I22) -> 9.6875
A23: 9qGVWb1 | D23: عمار الطحان | E23: علي بوصالح | F23: 7 | G23: 9 | H23: 9 | I23: 7 | J23: الأولويات عندي واضحة للأشهر القادمة وهذا رائع جدا التواصل بيننا جيد ولكن ممكن يفيدني تقييم متكرر بشكل أكبر، يساعدني أخرج من دوامة "أنا كيف هذي الفترة" أعتقد أن الأهداف الموضوعة أحيانا طموحة جدا فوق الواقعي، ما تأخذ بعين الاعتبار التعقيد الموجود في الصنعة مستندات المزايا المطلوبة أحسها انكتبت بسرعة أحيانا وفيها اختصار مخل | K23: 9 | L23: 9 | M23: 10 | N23: 10 | O23: الدعم اللي أشوفه شخصيا ممتاز، أحس اني مُمَكن عندما أحتاج | P23: 8 | Q23: 9 | R23: 9 | S23: 10 | T23: أحيانا أحس التحفيز السلبي (ليش تأخرنا هنا، خلونا نخلص هناك) يطغى على الايجابي (حبيت اننا ركزنا في هذي النقطة وخلصناها مثل المتوقع) | U23: 8 | V23: 9 | W23: 9 | X23: 9 | Y23: أحس ان مهارات القيادة (المهارات الناعمة) مغفول عنها في ثمانية عموما | AB23: بمجرد الإرسال، سيتم اعتماد تقييمك حول مديرك. هل أنت متأكد؟ | AC23: TRUE | AF23: =AVERAGE(U23:X23,P23:S23,K23:N23,F23:I23) -> 8.8125
A24: Gxxezxz | B24: GaYaoz | C24: 45754.562 | D24: محمد عطاالله | E24: علي بوصالح | F24: 10 | G24: 9 | H24: 9 | I24: 9 | J24: مديري ممتاز جدًا في توضيح الأفكار وتحديد الأولويات، وأسلوبه الواضح يجعل العمل أسهل علينا كفريق. لو في شيء بسيط ممكن نطوره، فهو إنه نراجع الأولويات مع بعض بشكل مستمر، خاصة لما يصير فيه تغييرات مفاجئة. | K24: 10 | L24: 10 | M24: 10 | N24: 8 | O24: مديري يُظهر تفهّمًا جيدًا لمشاعر الفريق، إلا أنه أحيانًا لا ينعكس ذلك على تخفيف حجم العمل أو مرونة المدة الزمنية بشكل يتناسب مع ضغط المهام. | P24: 10 | Q24: 10 | R24: 10 | S24: 9 | T24: قيادة مديري ملهمة جدًا، فهو يحفزنا باستمرار، ويشجع التعاون والروح الإيجابية داخل الفريق. وجوده يجعل بيئة العمل مشجعة ومريحة، ومشاركته لنا في اتخاذ القرارات تعزز شعورنا بالمسؤولية والانتماء. | U24: 8 | V24: 9 | W24: 9 | X24: 10 | Y24: مديري داعم جدًا ويساهم بشكل واضح في تطوير الفريق وتشجيع الأفكار الجديدة. سيكون رائعًا لو تم تخصيص وقت إضافي أحيانًا لجلسات تطوير فردية تساعد كل شخص على تحديد مساره المهني بشكل أوضح. بشكل عام دعمه وتحفيزه يعطينا طاقة إيجابية ويدفعنا نكون أفضل. | AB24: بمجرد الإرسال، سيتم اعتماد تقييمك حول مديرك. هل أنت متأكد؟ | AC24: TRUE | AF24: =AVERAGE(U24:X24,P24:S24,K24:N24,F24:I24) -> 9.375
A25: D44krG5 | B25: ANqyXe | C25: 45753.546 | D25: محمد الطويل | E25: عمار الطحان | F25: 9 | G25: 9 | H25: 9 | I25: 9 | J25: مديري يجيد ترتيب الأولويات | K25: 7 | L25: 7 | M25: 7 | N25: 7 | O25: مزيد من الثقة بقدرة الفريق | P25: 8 | Q25: 8 | R25: 8 | S25: 8 | T25: مشاركة الخطط المستقبلية مع الفريق | U25: 8 | V25: 8 | W25: 8 | X25: 8 | Y25: اسناد المزيد من المهام الصعبة لاعضاء الفريق | AB25: بمجرد الإرسال، سيتم اعتماد تقييمك حول مديرك. هل أنت متأكد؟ | AC25: TRUE | AF25: =AVERAGE(U25:X25,P25:S25,K25:N25,F25:I25) -> 8
A26: A77pqJk | B26: 6GrVgA | C26: 45754.538 | D26: محمد مصطفى | E26: عمار الطحان | F26: 8 | G26: 9 | H26: 8 | I26: 8 | J26: ليس لدى، لانها من الاشياء التى يبرع فيها، يقوم بها على اكمل وجه | K26: 8 | L26: 9 | M26: 9 | N26: 9 | O26: ليس لدى | P26: 8 | Q26: 10 | R26: 9 | S26: 7 | T26: بالنسبة لأخر نقطة تحتاج الى تحسين وهى مشارك الفريق فى أتخاذ القرارت. | U26: 8 | V26: 10 | W26: 8 | X26: 8 | Y26: ليس لدى | Z26: شكرا لك لقد جعلت بيئة العمل ايسر وافضل واضفت الكثير من التنظيم والجودة الى الفريق وبيئة العمل | AA26: لا شكرا | AB26: بمجرد الإرسال، سيتم اعتماد تقييمك حول مديرك. هل أنت متأكد؟ | AC26: TRUE | AF26: =AVERAGE(U26:X26,P26:S26,K26:N26,F26:I26) -> 8.5
A27: A77dG0N | B27: AN4goz | C27: 45755.193 | D27: محمد عاصم | E27: عمار الطحان | F27: 10 | G27: 10 | H27: 9 | I27: 9 | J27: لا يوجد | K27: 9 | L27: 9 | M27: 9 | N27: 9 | O27: لا يوجد | P27: 9 | Q27: 9 | R27: 9 | S27: 9 | T27: عمار يسمع لأراء الأشخاص ولكن اعتقد محتاج يسمع اكثر للاراء ووضع احتمالية ان يكون راي الاخرين افضل ولو بشكل بسيط | U27: 4 | V27: 6 | W27: 8 | Y27: نقطة التطوير دي بتبقي بناءً علي المجهود الشخصي. محتاجين يبقي في خطه ليها مع المدير | Z27: -وضع خطة لاعطاء الاشخاص فرصه للتطوير واعطاء الوقت ومراعاة ذلك في تحديد مدة المهمات. - استمرار تحفيز الاشخاص ومراعاة المجهود المبذول وصعوبة المهمات. -الشكر علي محاولة تحسين بيئة العمل وتحسين المشاكل الموجوده و محاولة حلها. | AA27: - عند طلب اجازه احس منه بصعوبة الموضوع واشتراطه احيانا بإنهاء مهمات معينه معه ان الاجازات ممكن تكون قهريه ولمدة يوم او اثنين وليس مده كبيره | AB27: بمجرد الإرسال، سيتم اعتماد تقييمك حول مديرك. هل أنت متأكد؟ | AC27: TRUE | AF27: =AVERAGE(U27:X27,P27:S27,K27:N27,F27:I27) -> 8.5333333
A28: Npqp57l | B28: jqJGB1 | C28: 45743.524 | D28: هادي حفني | E28: عمار الطحان | F28: 10 | G28: 10 | H28: 10 | I28: 10 | J28: وضوح الأهداف وتحديد الأولويات اثّر بشكل ايجابي على اداء الفريق وجودة المخرجات. | K28: 10 | L28: 10 | M28: 10 | N28: 5 | O28: طريقة العمل ممتازة بشكل عام واثّرت بشكل ايجابي وواضح على انتاجية الفريق، لكن في بعض الاحيان يجب المناقشة مع الفريق لفهم مشاعرهم تجاه بعض القرارات والتعامل معها | P28: 7 | Q28: 10 | R28: 8 | S28: 5 | T28: بعض القرارات تحتاج الي مناقشة اطول مع الفريق. | U28: 3 | V28: 10 | W28: 10 | X28: 10 | Y28: اجتماع المحطة الدورى (1 الي 1) جيد لمشاركة المرئيات، لكن لا يوجد خطة واضحة لتطويري مهنيًا وعمليًا. | Z28: بشكل عام اداء وانتاجية الفريق وجودة المخرجات تحسنت بشكل كبير عما سبق. | AB28: بمجرد الإرسال، سيتم اعتماد تقييمك حول مديرك. هل أنت متأكد؟ | AC28: TRUE | AF28: =AVERAGE(U28:X28,P28:S28,K28:N28,F28:I28) -> 8.625
A29: Gxexvge | B29: WXY9BR | C29: 45752.991 | D29: محمد بدر | E29: عمار الطحان | F29: 9 | G29: 9 | H29: 8 | I29: 9 | J29: لا، دائمًا يحدد اولويات الدورة بالترتيب من الأهم ثم المهم | K29: 9 | L29: 9 | M29: 9 | N29: 9 | O29: لا | P29: 9 | Q29: 9 | R29: 9 | S29: 9 | T29: لا | U29: 8 | V29: 8 | W29: 9 | X29: 9 | Y29: لا | AB29: بمجرد الإرسال، سيتم اعتماد تقييمك حول مديرك. هل أنت متأكد؟ | AC29: TRUE | AF29: =AVERAGE(U29:X29,P29:S29,K29:N29,F29:I29) -> 8.8125
A30: ODQA9jg | B30: Per81d | C30: 45736.757 | D30: نواف العُمري | E30: عمار الطحان | F30: =AVERAGE(F31:F36) -> 9.1666667 | G30: =AVERAGE(G31:G36) -> 8.3333333 | H30: =AVERAGE(H31:H36) -> 8 | I30: =AVERAGE(I31:I36) -> 7.8333333 | J30: عمار توب التوب | K30: =AVERAGE(K31:K36) -> 7.4166667 | L30: =AVERAGE(L31:L36) -> 7.75 | M30: =AVERAGE(M31:M36) -> 8.75 | N30: =AVERAGE(N31:N36) -> 7.9166667 | O30: لا | P30: =AVERAGE(P31:P36) -> 7.75 | Q30: =AVERAGE(Q31:Q36) -> 8.1666667 | R30: =AVERAGE(R31:R36) -> 7.5833333 | S30: =AVERAGE(S31:S36) -> 8.0833333 | T30: لا | U30: =AVERAGE(U31:U36) -> 7.3333333 | V30: =AVERAGE(V31:V36) -> 8.25 | W30: =AVERAGE(W31:W36) -> 7.75 | X30: =AVERAGE(X31:X36) -> 7.9166667 | Y30: لا | Z30: عمار شخص رهيب، ولمسنا وجوده من اول اسبوع له بالفريق. محظوظين فيه | AB30: بمجرد الإرسال، سيتم اعتماد تقييمك حول مديرك. هل أنت متأكد؟ | AC30: TRUE | AF30: =AVERAGE(U30:X30,P30:S30,K30:N30,F30:I30) -> 8
A31: 9qN1dWG | B31: A691az | C31: 45769.391 | D31: إبراهيم القرعاوي | E31: فيصل الغامدي | F31: 10 | G31: 10 | H31: 7 | I31: 7 | J31: من اوضح ما رأيت | K31: 7 | L31: 8 | M31: 8 | N31: 7 | O31: أحس أنك لا تهتم لحدود المسمى الوظيفي، وهذا يخلق ضغط على الفريق لأنه يضطر يسوي شغله وشغل غيره. ويقلل التركيز على المهام الرئيسية التي وجد لأجلها كل شخص | P31: 8 | Q31: 8 | R31: 7 | S31: 9 | T31: محزم مليان | U31: 5 | V31: 8 | W31: 6 | X31: 8 | Y31: لا | AB31: بمجرد الإرسال، سيتم اعتماد تقييمك حول مديرك. هل أنت متأكد؟ | AC31: TRUE | AF31: =AVERAGE(U31:X31,P31:S31,K31:N31,F31:I31) -> 7.6875
A32: J910P4z | B32: x1gp2d | C32: 45736.906 | D32: رامي هاشم | E32: فيصل الغامدي | F32: 10 | G32: 8 | H32: 9 | I32: 9 | J32: أتعلم منه | K32: 7 | L32: 7 | M32: 9 | N32: 9 | O32: ممتاز | P32: 8 | Q32: 8 | R32: 8 | S32: 8 | T32: قيادة فعالة | U32: 7 | V32: 8 | W32: 7 | X32: 7 | Y32: الفريق يحتاج منك أحيان الدعم المعنوي البناء | Z32: شكرأ على التطور إلي سويته لي وللفريق | AA32: فيصل من ٦شهور غير فيصل الحي وأكيد للأحسن | AB32: بمجرد الإرسال، سيتم اعتماد تقييمك حول مديرك. هل أنت متأكد؟ | AC32: TRUE | AF32: =AVERAGE(U32:X32,P32:S32,K32:N32,F32:I32) -> 8.0625
A33: QKod2Kk | B33: 8yXagz | C33: 45738.964 | D33: عبدالله الغامدي | E33: فيصل الغامدي | F33: 10 | G33: 9 | H33: 8 | I33: 8 | J33: غالبًا ماتكون واضح يعطيك العافية. | K33: 8 | L33: 7 | M33: 9 | N33: 8 | O33: أشوف من الجيد نشد على الموظفين الجدد، لكن لا ننسى أن التأقلم في فريقنا مب أسهل شيء. فعادي لو ياخذ الموظف وقته بشكل منطقي، لكن يهمني ما نخسر الناس الجيدة بالضغط عليهم طوال الوقت. | P33: 8 | Q33: 8 | R33: 7 | S33: 8 | T33: أظن قربك الحالي بشكل عام ممتاز، تعرف متى تشد ومتى ترخي على الفريق. فشكري الجزيل. | U33: 9 | V33: 9 | W33: 8 | X33: 8 | Y33: دائمًا ما تكون متعطش لتطوير الجميع. | AA33: ما أقولها مجاملة، لكن صدقًا لا أظن أن فيه شخص يعرف كيف يتعامل مع ثمانية «في الأعمال» كثره. | AB33: بمجرد الإرسال، سيتم اعتماد تقييمك حول مديرك. هل أنت متأكد؟ | AC33: TRUE | AF33: =AVERAGE(U33:X33,P33:S33,K33:N33,F33:I33) -> 8.25
A34: RGKq7p9 | B34: V7jEOj | C34: 45776.691 | D34: شهاب | E34: فيصل الغامدي | F34: 7 | G34: 5 | H34: 6 | I34: 5 | K34: 4 | L34: 6 | M34: 8 | N34: 5 | O34: يفوض، لكن أحيانًا يتدخل في تفاصيل وصغيرة الأمور. | P34: 5 | Q34: 7 | R34: 5 | S34: 6 | U34: 5 | V34: 7 | W34: 7 | X34: 6 | Y34: لا | Z34: لا | AA34: شاركت كثير لكن دون جدوى | AB34: بمجرد الإرسال، سيتم اعتماد تقييمك حول مديرك. هل أنت متأكد؟ | AC34: TRUE | AF34: =AVERAGE(U34:X34,P34:S34,K34:N34,F34:I34) -> 5.875
A35: jaeLBla | B35: 4DkpLk | C35: 45741.811 | D35: جمانة سكلوع | E35: لينا الشهري | F35: =AVERAGE(F36:F37) -> 9 | G35: =AVERAGE(G36:G37) -> 9 | H35: =AVERAGE(H36:H37) -> 9 | I35: =AVERAGE(I36:I37) -> 9 | J35: الأفضل في وضع الأولويات وجعلها واضحة بين الفريق | K35: =AVERAGE(K36:K37) -> 9.5 | L35: =AVERAGE(L36:L37) -> 9.5 | M35: =AVERAGE(M36:M37) -> 9.5 | N35: =AVERAGE(N36:N37) -> 9.5 | O35: طريقة العمل محفزة، وفي إحسان بالحرص على موازنة كمية المهام | P35: =AVERAGE(P36:P37) -> 8.5 | Q35: =AVERAGE(Q36:Q37) -> 9 | R35: =AVERAGE(R36:R37) -> 9.5 | S35: =AVERAGE(S36:S37) -> 8.5 | T35: ممتنة لجو التعاون الإيجابي الموجود في الفريق | U35: =AVERAGE(U36:U37) -> 9 | V35: =AVERAGE(V36:V37) -> 8.5 | W35: =AVERAGE(W36:W37) -> 9.5 | X35: =AVERAGE(X36:X37) -> 9.5 | Y35: الجهود كافية ووافية 🌟 | AB35: بمجرد الإرسال، سيتم اعتماد تقييمك حول مديرك. هل أنت متأكد؟ | AC35: TRUE | AF35: =AVERAGE(U35:X35,P35:S35,K35:N35,F35:I35) -> 9.125
A36: EkqLBQL | B36: 6zKxgo | C36: 45740.753 | D36: وفاء العتيبي | E36: لينا الشهري | F36: 9 | G36: 9 | H36: 9 | I36: 9 | J36: - | K36: 9 | L36: 9 | M36: 9 | N36: 9 | O36: - | P36: 9 | Q36: 9 | R36: 9 | S36: 9 | T36: - | U36: 9 | V36: 9 | W36: 9 | X36: 9 | Y36: - | AB36: بمجرد الإرسال، سيتم اعتماد تقييمك حول مديرك. هل أنت متأكد؟ | AC36: TRUE | AF36: =AVERAGE(U36:X36,P36:S36,K36:N36,F36:I36) -> 9
A37: 9qNO41Y | B37: ANkrGy | C37: 45760.564 | D37: أحمد عيد | E37: لينا الشهري | F37: 9 | G37: 9 | H37: 9 | I37: 9 | J37: لا اواجه اي مشكلة هنا | K37: 10 | L37: 10 | M37: 10 | N37: 10 | O37: - | P37: 8 | Q37: 9 | R37: 10 | S37: 8 | T37: لو ممكن نشوي اجتماع نتبادل فيها خبرات كل فرد بحيث نفيد بعد كفريق | V37: 8 | W37: 10 | X37: 10 | Y37: - | Z37: لو نرجع نجتمع من جديد بكل دوري مرتين اسبوعيا بيكون امر لطيف .. الاجتماع بالنسبة أمر بسد بيه فجوة العمل عن بعد | AB37: بمجرد الإرسال، سيتم اعتماد تقييمك حول مديرك. هل أنت متأكد؟ | AC37: TRUE | AF37: =AVERAGE(U37:X37,P37:S37,K37:N37,F37:I37) -> 9.2666667
A38: kdb07gJ | B38: LBgpXO | C38: 45756.614 | D38: عبدالله مقيبل | E38: محمد الحرازي | F38: 6 | G38: 5 | H38: 7 | I38: 7 | J38: ممكن نتناقش عن تقسيم المهام بشكل دائم مع الفريق و نقسم تقسيمة معتدلة لكل شخص | K38: 6 | L38: 7 | M38: 5 | N38: 4 | O38: كل شخص عندة ظروفة و حياتة الخارجية الي صعب احيانا يصرح عنها ، وكل شخص يحاول يعطي العمل حقة و يقفل العمل بي اكمل وجه و برضو يعطي لحياته الخارجية حقها ، بس . و لازم نعرف انو لكل مهمه لها تحدياتها و كل حلقة او تشويقة نشتغل عليها لابد يكون فيها تحدي معين ، وما اذكر اني قد اشتغلت على مهمة وما كان فيها تحدي من الإنتاج او في التحرير و آلخ.. ، و يأخرني ، فلازم نحسب حساب هذا الشي | P38: 6 | Q38: 7 | R38: 7 | S38: 3 | T38: لا يوجد | U38: 5 | V38: 6 | W38: 6 | X38: 9 | Y38: لا يوجد | Z38: لا يوجد | AA38: لا يوجد | AB38: بمجرد الإرسال، سيتم اعتماد تقييمك حول مديرك. هل أنت متأكد؟ | AC38: TRUE | AF38: =AVERAGE(U38:X38,P38:S38,K38:N38,F38:I38) -> 6
A39: b5Z2Dv7 | B39: Ee22p4 | C39: 45760.507 | D39: عمر صافية | E39: محمد الحرازي | F39: 5 | G39: 6 | H39: 8 | I39: 6 | J39: أتمنى تعيين مدير عمليات يكون لديه الإطلاع والتنسيق بين تقاطعات الفرق المختلفة لتجنب المهام في اللحظات الأخيرة أو تجنب تمطيط المهام بلا داعي | K39: 8 | L39: 7 | M39: 8 | N39: 7 | O39: أن يكون أوضح فيما يتوقعه مني، وأن يحفزني ويوجهني لمكامن قوتي | P39: 7 | Q39: 7 | R39: 7 | S39: 6 | T39: أن يكون هناك لحمة وتفاعل أكبر بين الفريق وتعرف أكبر على بعضهم الآخر، وأن نجري اجتماعات أكبر فهي كفيلة بخلق تبادل إبداعي | U39: 5 | V39: 6 | W39: 6 | X39: 7 | Y39: أن يدلني أكثر على مكامن القوة التي يجب استغلالها، وينبهني على مكامن الضعف التي ينبغي تحسينها | AB39: بمجرد الإرسال، سيتم اعتماد تقييمك حول مديرك. هل أنت متأكد؟ | AC39: TRUE | AF39: =AVERAGE(U39:X39,P39:S39,K39:N39,F39:I39) -> 6.625
A40: zxE0vL8 | B40: 8VAldo | C40: 45754.825 | D40: محمد نور | E40: محمد الحرازي | F40: 7 | G40: 7 | H40: 7 | I40: 7 | J40: جيد جدا وتحسن ملحوظ في ترتيب المهام والاوليات | K40: 8 | L40: 7 | M40: 6 | N40: 6 | O40: تحسن ملحوظ في عدة نواحي ابرزها الذكاء العاطفي | P40: 7 | Q40: 7 | R40: 7 | S40: 8 | T40: اتوقع امورنا تمام ، مافي بالي شي معين | U40: 7 | V40: 7 | W40: 7 | X40: 7 | Y40: ليس لدي شي اضافي ، وفي اعتقادي ان الرغبة في التطوير والتطور ينبع من النفس | AB40: بمجرد الإرسال، سيتم اعتماد تقييمك حول مديرك. هل أنت متأكد؟ | AC40: TRUE | AF40: =AVERAGE(U40:X40,P40:S40,K40:N40,F40:I40) -> 7
...

Sheet تحليل تقييم 2025 - مايو
A1: القائد | B1: 📈 نقاط القوة | C1: 📉 نقاط الضعف | D1: ✅ التوصيات | E1: 👥 الفريق المثالي | F1: 🛠️ خطوات عملية | G1: 📊 مقارنة بـ 2024 وباقي القادة
A2: أسيل باعبدالله | B2: 1. أسلوب تواصلي إيجابي ومحبب للفريق. 2. حضور واضح كقائدة ملهمة وليس مجرد مشرفة. 3. تتميز بحماس ونشاط دائم ينعكس على طاقة الفريق. 4. قادرة على التعامل مع ضغوط العمل. 5. تقدّر أعضاء الفريق وتشكر جهودهم. 6. تفتح الباب للتطوير وتقبل النقد بصدر رحب. | C2: 1. تدخل مفرط في تفاصيل يومية، يخلق ضغطًا على الفريق. 2. تذبذب في ترتيب الأولويات، مما يربك الموظفين. 3. غياب التوثيق والمرجعية الواضحة للقرارات. 4. لا توجد جلسات دورية كافية مع الموظفين لمراجعة الأداء. 5. تعليقات متكررة عن قلة الثقة في الفريق رغم النوايا الطيبة. 6. الفريق يشعر أنه يُعامل وكأنه "مبتدئ" طوال الوقت. | D2: 1. تقليل التدخل في المهام التفصيلية بعد التفويض. 2. بناء هيكل واضح للأولويات الشهرية. 3. جلسات 1:1 دورية مع كل موظف. 4. كتابة وتوثيق المشاريع والمهام في Basecamp. 5. تعيين مساعد/منسق مشاريع يخفف الضغط عنها. 6. ضبط سقف التوقعات الواقعي، وتوضيحه مسبقًا. | E2: - فرق صغيرة مبدعة تحتاج إلهامًا وليس إدارة مباشرة. - يجب وجود مدير مشروع/منسق يساعدها في المتابعة اليومية. | F2: 1. اجتماع شهري لمراجعة الأولويات الجماعية. 2. تخصيص وقت أسبوعي للمرئيات الفردية. 3. تفويض جزئي لمهام التشغيل مع مراقبة النتائج فقط. 4. استخدام وثائق Google واضحة لمهام كل شخص. 5. تخصيص ساعة أسبوعيًا لتوثيق ما تم وما هو قادم. 6. توزيع المهام حسب مبدأ الثقة لا الرقابة. | G2: - تراجع في تقييمها مقارنة بـ 2024. - تعاني من نفس نقاط الضعف التي اشتكى منها الفريق سابقًا. - مقارنة بأنس أو عبدالوهاب، تقييمها أقل بسبب الضغط والإرباك اليومي للفريق.
A3: أنس الأهدل | B3: 1. محبوب جدًا من الفريق. 2. يجيد تحفيز الموظفين بشكل غير مباشر. 3. يتعامل بود واحترام حتى في أوقات التوتر. 4. واضح في التعليمات ومهتم بالجودة. 5. يخلق مساحة نفسية مريحة للأفكار. 6. يعامل الجميع على قدم المساواة. | C3: 1. قد يكون مفرطًا في "اللطف" ما يسبب ترددًا في الحزم. 2. مساحة التجريب والابتكار خارج الخطة الرسمية قليلة. 3. بعض الأفراد يشعرون أن “المثالية” تعيق سرعة القرارات. 4. لا يوجد دائمًا مرجعية واضحة للمهام. 5. محدودية التوجيه المكتوب. 6. عدم وضوح في بعض الحدود الإدارية بين الفريق والمدير. | D3: 1. إدخال أدوات توثيق للقرارات والتوجيهات. 2. تشجيع الفريق على التجريب خارج الخطة. 3. تعزيز مفهوم "الخطأ الآمن" لتقليل الخوف من المخاطرة. 4. زيادة التواصل الكتابي للمشاريع. 5. مراجعة شهرية لكل عضو لمعرفة العقبات. 6. تدريب أحد الفريق على أن يكون مساعده التنفيذي. | E3: - فرق تعتمد على الثقة والانضباط الذاتي. - موظفون مبتكرون يفضلون بيئة لا مركزية. | F3: 1. تخصيص مساحة أسبوعية للاقتراحات الخارجة عن الخطة. 2. توثيق المهام الرئيسية في لوحة Trello أو Google Sheet. 3. استخدام رسائل Basecamp للرد على الاستفسارات المتكررة. 4. تدريب أعضاء الفريق على اتخاذ قرارات مستقلة. 5. تعيين قائد ثانوي لكل مشروع لتقليل الاعتماد المباشر عليه. 6. جلسة ربع سنوية للتغذية الراجعة الصريحة مع الفريق. | G3: - تراجع طفيف عن 2024 لكنه ما زال الأعلى في “الثقة”. - أفضل مدير من حيث “الراحة النفسية” مقارنة بالآخرين.
A4: عبدالرحمن أبومالح | B4: 1. ملهم وذكي وله نظرة استراتيجية قوية. 2. يعطي مساحة للرأي والنقاش. 3. يعبر عن رؤيته بشكل واضح. 4. يحفز الناس بأسلوب غير مباشر. 5. يقدّر العاملين معه ويحترمهم. 6. مرن وقابل لتعديل الآراء. | C4: 1. التوقعات غير المعلنة تربك الفريق. 2. تغييرات مفاجئة دون تهيئة أو شرح كافٍ. 3. التوجيه غالبًا شفهي وغير موثق. 4. يترك بعض التفاصيل معلقة دون مسؤول واضح. 5. الفريق أحيانًا "يحاول يقرأ النية". 6. التعامل غير المنتظم في إدارة المشاريع. | D4: 1. كتابة الخطة الكبرى مع أهداف ربع سنوية واضحة. 2. استخدام وسيلة واحدة للاتصال (Basecamp فقط). 3. تخصيص وقت دوري للإجابة على تساؤلات الفريق. 4. تقليل تغيير المسار بدون نقاش مسبق. 5. تكوين مجلس مصغّر يساعد في نقل الرؤية. 6. تعيين مدير مشروع يترجم الرؤية اليومية للفريق. | E4: - فرق ناضجة فكريًا، تعتمد على توجيه إستراتيجي لا يومي. - تحتاج وسيط إداري بينه وبين المنفذين. | F4: 1. إرسال ملخص أسبوعي للقرارات والتغييرات. 2. اعتماد قالب وثيقة “رؤية المشروع” لأي فكرة جديدة. 3. عقد جلسة “أسئلة مفتوحة” شهرية مع الفريق. 4. تدريب مدير مشروع مساعد لتقليل الحيرة. 5. هيكلة مراجعات ربع سنوية للأداء والاتجاه. 6. تقليل توجيه اللحظة، واستبداله بتوجيه مكتوب. | G4: - تراجع واضح عن 2024. - فقدان الوضوح هو العامل الأبرز في التراجع. - من أعلى المدراء في التأثير، لكن من الأقل وضوحًا.
A5: علي بوصالح | B5: 1. حريص على التوثيق والمراجعة. 2. يقدّر العمل الجيد ويشكر عليه. 3. يُظهر انفتاحًا على الأفكار المختلفة. 4. يبني علاقات جيدة داخل الفريق. 5. يعمل بمرونة ويتفهم الظروف. 6. لديه حس تنظيم عالي في المشاريع. | C5: 1. تأخر في الردود والتوجيه أحيانًا. 2. لا يتابع تفاصيل المهام بعد التفويض. 3. بعض الموظفين يشعرون بأنه "بعيد" عن التفاصيل اليومية. 4. لا يوضح المعايير التي يقيم عليها الفريق. 5. تباين في مستوى الدعم بين أعضاء الفريق. 6. يحتاج لمزيد من الحزم أحيانًا في مواجهة الأخطاء. | D5: 1. وضع نظام متابعة أسبوعي ثابت للمهام. 2. تحسين سرعة الرد على استفسارات الفريق. 3. تحديد معايير واضحة للتقييم. 4. استخدام أدوات مرئية لمتابعة المهام. 5. مراجعة الأداء مع كل عضو شهريًا. 6. وضع خطة تطوير فردية لكل عضو. | E5: - فريق منظم، يحب الحرية التشغيلية، لكنه يحتاج وضوحًا في التوقعات. | F5: 1. إرسال جدول أسبوعي لتوزيع المهام. 2. تخصيص وقت ثابت أسبوعيًا للرد على الفريق. 3. تصميم نموذج لتقييم الأداء داخل الفريق. 4. اعتماد Check-ins سريعة مع كل فرد. 5. تعيين مساعد إداري لمساعدته في المتابعة. 6. تخصيص وقت للملاحظات المكتوبة على Basecamp. | G5: - تقييم مستقر لكن يفتقر للتحفيز العالي أو الانتقاد الكبير. - يعتبر من "المدراء الصامتين" مقارنةً بأنس أو عبدالرحمن.
A6: فيصل الغامدي | B6: 1. محترم في تعامله مع الجميع. 2. واضح في التوجيه. 3. يترك مساحة للفريق لاتخاذ القرار. 4. سريع في معالجة المشكلات. 5. يستوعب ضغوط العمل بهدوء. 6. يهتم بتطوير الأداء بشكل ملحوظ. | C6: 1. بعض الأعضاء لا يفهمون الأولويات بدقة. 2. لا يشارك أهدافه طويلة المدى. 3. دعم محدود عند حدوث خلل كبير. 4. ردود متأخرة في أوقات الضغط. 5. لا يراجع خطط الفريق بشكل كافٍ. 6. يغلب عليه الأسلوب التنفيذي دون رؤية واضحة. | D6: 1. إعداد خطة واضحة لمهام الفريق شهريًا. 2. تعزيز حضور القيادة بتوجيهات استراتيجية. 3. تخصيص وقت للملاحظات الجماعية المكتوبة. 4. التخفيف من الحمل التنفيذي بالاعتماد على الفريق. 5. إنشاء لوحة مهام واضحة للكل. 6. تقييم الأداء دوريًا بطريقة مفهومة. | E6: - فرق إنتاجية تعرف عملها، تحتاج وضوحًا لا متابعة مكثفة. | F6: 1. إرسال قائمة أسبوعية بالمهام والأولويات. 2. فتح جلسة نصف شهرية للأسئلة المفتوحة. 3. إشراك الفريق في وضع خطط قصيرة المدى. 4. اعتماد Google Sheet مشترك للمشاريع. 5. اعتماد شخص مساعد لمهام التشغيل. 6. تصميم ملف رؤية شهري للفريق. | G6: - أداء متقارب مع 2024. - من الأقل جدلًا، ومن الأقل تركيزًا في التعليقات.
A7: عبدالوهاب محمد | B7: 1. قائد ملهم بالفطرة. 2. دائم التشجيع ومُحب للفريق. 3. صادق في مرئياته ويدعم التطوير. 4.، يخلق بيئة محفزة وودية. 5. يشارك النجاح مع الفريق. 6. توجيهاته فعالة وغير متسلطة. | C7: 1. خطر تحميله أكثر من طاقته. 2. أحيانًا يميل للاندماج في كل التفاصيل. 3. لا يضع حدودًا واضحة بينه وبين مهام الفريق. 4. كثرة الأدوار تقلل من فعاليته كقائد. 5. بعض الأعضاء لا يتلقون مرئيات كافية. 6. يحتاج فصلًا بين دوره الإداري والفني. | D7: 1. قصر مهامه على الإدارة والتطوير، لا الإنتاج. 2. تعيين مدير تنفيذ تحت إشرافه. 3. توثيق المرئيات بعد كل مشروع. 4. جدول شهري للقاء الفريق حول الأداء. 5. التركيز على التخطيط أكثر من التشغيل. 6. توزيع المهام بشكل استراتيجي، لا عاطفي. | E7: - فريق متعدد المهارات بحاجة لقائد ثقافي وأخلاقي. - يجب وجود قائد فني معه للجانب التشغيلي. | F7: 1. تحديد سقف المهام المقبولة له. 2. تعيين مسؤول إنتاج يدير المصورين. 3. توثيق مراجعات الأداء نصف شهرية. 4. تقليل عدد المشاريع المفتوحة في وقت واحد. 5. تدريب نائب إداري يساعده في المتابعة. 6. التفرغ للجانب القيادي والتخطيط طويل المدى. | G7: - قفزة نوعية مقارنة بـ 2024. - الأعلى في “الثقة” و“الدعم”، مع ملاحظات حول الإجهاد. - مقارنة بالبقية: الأقوى عاطفيًا وإنسانيًا، يحتاج دعمًا إداريًا.
A8: عبدالله الغامدي | B8: 1. يحب التطوير وتحسين آليات العمل. 2. منفتح للنقد والتعديل. 3. ملتزم بالنتائج النهائية. 4. يملك قدرة على رؤية التفاصيل. 5. مهتم بجودة الإنتاج. 6. يحاول دعم الفريق رغم التحديات. | C8: 1. تدخّل في التفاصيل حتى بعد التفويض. 2. قرارات تتغير فجأة وبدون شرح. 3. الأولويات غير واضحة ولا يُراجعها دوريًا. 4. يراقب الفريق بطريقة تضيف توترًا. 5. المركزية والاعتماد على الذات في المتابعة. 6. لا يملك آلية تنظيمية ثابتة. | D8: 1. وثّق الأولويات كل أسبوعين في ملف واضح. 2. بعد التفويض، راقب عن بعد ولا تتدخل إلا عند الخلل. 3. نظّم جلسات مراجعة سريعة (15 دقيقة) كل أسبوع. 4. استخدم أدوات مؤشرات الأداء لمتابعة النتائج بدون تدخل. 5. فصّل المهام الكبرى ووزع المسؤوليات بدقة. 6. راجع الهيكل الإداري لمشاريعك وتأكد أن لكل مشروع مديرًا واضحًا. | E8: - فرق إنتاجية عملية تحتاج توجيهًا واضحًا. -ريشترط وجود تنفيذيين مساعدين لمتابعة التفاصيل. | F8: 1. هيكلة ملف “أولويات الشهر” بصيغة قابلة للتعديل. 2. توثيق المهام لكل شخص أسبوعيًا. 3. تدريب مساعد مدير مشروع. 4. تقليل الاجتماعات الطويلة والتركيز على التحديثات المكتوبة. 5. استخدام Dashboards لمتابعة التنفيذ. 6. تخصيص ساعة أسبوعيًا فقط للتوجيه العام. | G8: - تقييم شبه ثابت منذ 2024. - لم تحدث نقلة نوعية، لكن لا يزال الفريق يعاني من نفس المشكلة. - مقارنة بالبقية: جيد في التحفيز، ضعيف في التنظيم.
A9: عمار الطحان | B9: 1. قيادي حازم وواضح في التوجيه. 2. يركز على النتائج. 3. سريع في اتخاذ القرار. 4. يهتم بجودة الإخراج النهائي. 5. دقيق في المواعيد والانضباط. 6. يعمل بهدوء دون توتر الفريق. | C9: 1. لا يعطي مساحات كثيرة للحوار. 2. لا يشارك خلفية قراراته. 3. يفتقر لأسلوب التشجيع العاطفي. 4. قد يُشعر الفريق أنه تحت رقابة دائمة. 5. لا يستخدم التغذية الراجعة بشكل منتظم. 6. قلة في التواصل غير الرسمي. | D9: 1. إضافة جلسات 1:1 شهرية. 2. مشاركة الرؤية خلف القرارات الكبرى. 3. استخدام أسلوب سؤال-جواب بدل إعطاء التعليمات فقط. 4. تشجيع الإبداع لا الالتزام فقط. 5. مشاركة الإنجازات مع الفريق. 6. جعل النجاح "جماعياً" وليس فرديًا. | E9: - فرق عملياتية، واضحة الهيكل، تحب العمل الدقيق وليس الإبداعي. | F9: 1. تحديد أهداف قصيرة المدى واضحة مع الفريق. 2. فتح مساحة للحوار الشهري. 3. استخدام تقارير مرئية لعرض الأداء بدل النقد الفردي. 4. تخصيص وقت للإجابة على استفسارات الفريق كتابيًا. 5. استخدام استطلاع شهري سريع لقياس الرضا. 6. إتاحة التجريب مرة شهريًا في مشاريع غير رسمية. | G9: - تقييم متوسط، لا نقد حاد ولا مدح عاطفي. - مقارنة بالبقية: قوي في النتائج، أضعف في المشاعر والمرونة.
A10: لينا الشهري | B10: 1. تتواصل بلطف واحترام. 2. تُظهر تعاطفًا وتفهمًا مع الفريق. 3. تهتم بالملاحظات وتسمع جيدًا. 4. تخلق بيئة آمنة للحوار. 5. تعزز الجانب الإنساني في الإدارة. 6. لا تفرض نفسها أو تتسلط. | C10: 1. الحزم غير واضح في لحظات اتخاذ القرار. 2. أحيانًا تتردد في التدخل الحاسم. 3. الأولويات تتغير دون إشعار كافٍ. 4. مهام بعض الأعضاء غير واضحة. 5. بعض الفريق يشعر بالغموض في التوجيه. 6. ضعف استخدام الأدوات التوثيقية. | D10: 1. توضيح مسؤوليات كل فرد في الفريق كتابيًا. 2. تعزيز الحزم وقت الخلل دون التنازل عن اللطف. 3. استخدام أدوات لإدارة الأولويات (Trello / Basecamp). 4. توثيق جميع النقاشات الكبرى. 5. تكرار الأهداف بشكل دوري أمام الفريق. 6. إدخال منهجية "ما تم/ما القادم" أسبوعيًا. | E10: - فرق حساسة أو جديدة، تحتاج دعمًا نفسيًا عاليًا وأسلوبًا إنسانيًا. | F10: 1. فتح جلسة تقييم أداء شهرية مع الفريق. 2. تحديد أولويات مكتوبة أسبوعيًا. 3. اعتماد مرجع واضح للقرارات الرئيسية. 4. تدريب أحد الأعضاء ليكون منسقًا معها. 5. إعداد مسار تطوير فردي لكل عضو. 6. استخدام ملاحظات جماعية بعد كل مشروع. | G10: - تقدمت عن 2024 في الثقة، لكن الثبات ما زال ظاهرًا. - مقارنةً بعلي أو عمار: قوية إنسانيًا، بحاجة لحسم إداري أقوى.
A11: محمد الحرازي | B11: 1. واضح ومنظم جدًا. 2. يهتم بالنتيجة والجودة. 3. لا يضغط على الفريق ميدانيًا. 4. يُظهر هدوءًا في القيادة. 5. يعامل الفريق بموضوعية. 6. يُركّز على التفاصيل المهمة فقط. | C11: 1. لا يُشارك أبعاد القرارات دائمًا. 2. لا يعطي مساحة كافية للإبداع. 3. التوجيه أحيانًا يكون آمرًا لا نقاشيًا. 4. لا يُراجع الأداء إلا عند الخطأ. 5. قلة الدعم العاطفي. 6. البعض يشعر أنه بعيد عن الفريق. | D11: 1. مشاركة السياق الكامل خلف القرارات. 2. تخصيص وقت شهري للأسئلة والاقتراحات. 3. توضيح معايير التقييم بانتظام. 4. تشجيع التجريب ولو جزئيًا. 5. تنظيم جلسات 1:1 دورية. 6. دمج مرئيات الفريق في التحسينات. | E11: - فرق تقنية أو تنفيذية عالية الانضباط، ولا تحتاج دعمًا عاطفيًا كبيرًا. | F11: 1. إرسال مستند شهري للتحديثات. 2. تفعيل قنوات استلام الاقتراحات. 3. تقليل صيغة "افعل" وزيادة "نقترح أن". 4. تفعيل قائمة تتبع المهام مع متابعة أسبوعية. 5. إدخال عنصر "الاحتفال بالنجاح". 6. تقليل الفجوة بينه وبين أعضاء الفريق الصامتين. | G11: - أداء ثابت مقارنة بـ 2024. - يُعد من أكثر المدراء تنظيمًا، لكن أقلهم مرونة.
A12: محمد عطالله | B12: 1. واضح جدًا في رؤيته. 2. يضع أهدافًا واقعية ومنظمة. 3. يهتم بتحسين مستوى الفريق. 4. يُشجّع على التطوير المستمر. 5. يتعامل باحترام ولا يتسلط. 6. منفتح للأفكار الجديدة. | C12: 1. لا يشارك خطط التطوير علنًا. 2. الفريق أحيانًا يجهل الأولويات. 3. لا توجد مراجعات أداء دورية. 4. التوقعات غير مكتوبة. 5. يحتاج دعمًا إداريًا لمتابعة التفاصيل. 6. بعض أعضاء الفريق يرون الفجوة في التواصل. | D12: 1. كتابة خطة عمل شهرية مع مراجعة واضحة. 2. تحديد أهداف لكل عضو في بداية كل ربع. 3. إشراك الفريق في التخطيط الدوري. 4. مراجعة الأداء بشكل رسمي كل 45 يوم. 5. توثيق كل مشروع أو تغيير في Google Docs. 6. تفعيل مراجعة 360 درجة كل 6 أشهر. | E12: - فرق تركز على التحسين المستمر، ولديها حس المبادرة العالي. | F12: 1. إنشاء وثيقة الأولويات الشهرية. 2. تحديد وقت للأسئلة المفتوحة مع الفريق. 3. تعيين مساعد إداري لمتابعة التنفيذ. 4. استخدام Dashboard لتتبع الأداء. 5. إشراك الفريق في KPIs. 6. إرسال تقرير أداء ربع سنوي لكل عضو. | G12: - تحسن واضح عن 2024 في المرونة والتواصل. - مقارنة ببقية المدراء، هو في "المنطقة الدافئة"؛ جيد لكنه يحتاج نقلته النوعية التالية.
... A18: وديان بحه | B18: 1. شخص منظم جدًا. 2. واضحة وصادقة في التواصل. 3. تعطي الفريق مساحات جيدة. 4. تنظم أولويات العمل بفعالية. 5. تتابع المهام دون إزعاج. 6. تساعد بدون فرض. | C18: 1. أحيانًا تتأخر في إعطاء التغذية الراجعة. 2. بعض التوجيهات غير واضحة. 3. لا يتم مشاركة الصورة الكبرى دائمًا. 4. الفريق لا يعرف أحيانًا كيف يتم تقييمه. 5. لا توجد جلسات تطوير رسمية. 6. الفصل بين العلاقات والعمل ضعيف أحيانًا. | D18: 1. مشاركة الخطة الكبرى مع الفريق كل شهر. 2. تصميم وثيقة أهداف. 3. تقليل التوجيه غير المكتوب. 4. تفعيل تقييم الأداء الفردي. 5. إدخال أدوات دعم إداري. 6. تحديد وقت للقرارات الحاسمة كل أسبوع. | E18: - فرق تحب التنظيم ولا تحب التكرار أو المفاجآت. | F18: 1. إرسال خطة مكتوبة كل أسبوعين. 2. تقويم مواعيد التغذية الراجعة. 3. فتح تقييم 360 درجة كل 6 أشهر. 4. اعتماد Google Doc مشترك للأهداف. 5. متابعة الأداء KPI نصف شهري. 6. تحديد وقت “نقاش صريح” شهري. | G18: - تقدم ملحوظ مقارنة بـ 2024، وتقييم عالٍ في "النظام والوضوح".

Sheet 2024 مقارنة ب 2025
B1: تقييم القادة 2024 - 2025 | J1: أغسطس 2024
B2: متوسط تقييم القادة | D2: 8.2 | F2: 7.91 | J2: متوسط تقييم القادة | L2: 8 | N2: 7.91
B3: عدد التقييمات | D3: 85 | F3: 85 | J3: عدد التقييمات | L3: 85 | N3: 85
B4: عدد المجاملين المستبعدين | D4: 10 | F4: 5 | J4: عدد المجاملين تم إبعادهم | L4: 10 | N4: 5
B5: عدد القادة | D5: 23 | F5: 20 | J5: عدد المدراء | L5: 23 | N5: 20
E8: من الأعلى للأقل⬇ | K8: من الأعلى للأقل⬇
C9: أغسطس 2024 | E9: أبريل 2025 | G9: مقارنة بين الدورتين | H9: توصيات الموارد البشرية | K9: أغسطس 2024 | M9: أبريل 2025
B10: إسم المدير | C10: متوسط التقييم | D10: عدد المُقيمين | E10: متوسط التقييم | F10: عدد المُقيمين | J10: إسم المدير | K10: متوسط التقييم (بعد تعديل المجاملين) | L10: عدد المُقيمين | M10: متوسط التقييم (بعد تعديل المجاملين) | N10: عدد المُقيمين
B11: إبراهيم القرعاوي | C11: 6.9375 | D11: 7 | E11: - | F11: 1 | H11: توظيف فريق أكبر (1-2 منتجي محتوى) بالاضافة التركيز على المهام والمشاريع المفتوحة والعالقة. والتفرغ الكامل للاستديوهات. متى يكون جاهز ليرجع إداريًا لأبومالح؟ | J11: إبراهيم القرعاوي | K11: 6.9375 | L11: 7 | M11: - | N11: 1 | O11: ⬆
B12: البراء العوهلي | C12: 9.25 | D12: 2 | E12: - | F12: 1 | H12: التركيز على فريق الثقافة الحالي، وتوزع المهام والأدوار بفعالية بحسب مستوى وراتب كل فرد. يحتاج أن يلتزم بالخط الزمني للمشاريع، ويحدد الأولويات، خاصة بما يخص "في ثمانية". | J12: البراء العوهلي | K12: 9.25 | L12: 2 | M12: - | N12: 1 | O12: ⬇
B13: شهاب سمير | C13: 9.40625 | D13: 2 | E13: - | F13: 0 | H13: يحتاج توظيف 1-2 في المالية، حتى يتمكن من مشاركة أدوار أكبر مع مصطفى وأحمد -مع ضرورة كونهم سعوديين لأسباب رقابية-. | J13: شهاب سمير | K13: 9.40625 | L13: 2 | M13: - | N13: 0
B14: عبدالقدوس | C14: 9.0416667 | D14: 3 | E14: - | F14: 1 | H14: تطوير قيادته وتوظيفه لفريق الموارد البشرية. التركيز على الأولويات واغلاق المهام العالقة. | J14: عبدالقدوس | K14: 9.0416667 | L14: 3 | M14: - | N14: 1
B15: وهاب محمد | C15: 7.390625 | D15: 4 | E15: 9.33 | F15: 3 | G15: ⬆⬆ | H15: أثبت إدارته لفريقه + إدارة البيانات. الاقتراح أنه يتولى فريق المنتجين + موفق. | J15: وهاب محمد | K15: 7.390625 | L15: 4 | M15: 9.33 | N15: 3
B16: معاذ الحربي | C16: 7.4375 | D16: 3 | E16: 9.25 | F16: 2 | G16: ⬆⬆ | H16: يحتاج لتوظيف فريق أكبر وفريق متواجد في المكتب ومتوائم مع ثقافة ثمانية. يحتاج مراجعة المستهدفات الفعلية للقسم حتى يتأكد لعدم إهماله لفريق معين. وتمكين القادة «رزان ولينا» | J16: معاذ الحربي | K16: 7.4375 | L16: 3 | M16: 9.25 | N16: 2
B17: علي بوصالح | C17: 9.0714286 | D17: 7 | E17: 9.09 | F17: 2 | H17: لا زال ضغط فريق التقنية مرتفع. حاب أعرف لو دخول الموظفين الجدد -خاصة في إدارة المنتج- ساعد؟ هل نحتاج نوظف أكثر؟ مسؤوليات علي لا تنتهي، وخاصة المزايا الجديدة في تطبيق راديو ثمانية، لازم يحدد الأولويات ويضع خطة واضحة لتطوير منتجات ثمانية التقنية. يحتاج يعطي مسؤولية أكبر للفريق، خاصة عطالله. لازم ينتبه على أداء الفريق، ويفصل الضعيف منهم، خاصة لمن يحتاج متابعة دائمة أو تدقيق في جودة البرمجة والمخرجات. | J17: علي بوصالح | K17: 9.0714286 | L17: 7 | M17: 9.09 | N17: 2
B18: لينا الشهري | C18: - | E18: 9.01 | F18: 3 | H18: تحتاج لتمكين أكبر، تكون متواجدة بشكل أكبر وتركز على الجانب الإداري أكثر من الإبداعي. | J18: لينا الشهري | K18: - | M18: 9.01 | N18: 3
B19: مشاري الحمود | C19: 8.140625 | D19: 8 | E19: 8.8 | F19: 8 | G19: ⬆ | H19: يحتاج يعين قادة تحته، لتخفيف الموظفين المباشرين إلى 6 كحد أقصى، حتى يلتزم أكثر في المواعيد والتدقيق في المحتوى. | J19: مشاري الحمود | K19: 8.140625 | L19: 8 | M19: 8.8 | N19: 8
B20: موفق | C20: - | E20: 8.76 | F20: 5 | H20: أموره تمام، لكنه دائمًا يطلب راتب أعلى ب25٪ من الحالي، ف هل هو مرتاح؟ فريقه مضغوط، كانوا 6 مخرجين واللحين 3 فقط، مع زيادة المشاريع. | J20: موفق | K20: - | M20: 8.76 | N20: 5
B21: محمد عطاالله | C21: 8.6875 | D21: 3 | E21: 8.51 | F21: 6 | H21: يحتاج يطور من قيادته للفريق، ويشدد عليهم، ويعين قادة معه. | J21: محمد عطاالله | K21: 8.6875 | L21: 3 | M21: 8.51 | N21: 6
B22: أنس الأهدل | C22: 8.2291667 | D22: 6 | E22: 8.28 | F22: 6 | H22: مع تغييرات هيكلة فريق التسويق، نختبر لو أنس فعليًا بمثابة "نائب رئيس" لفريق النمو والنشر، أو نحدد دوره لأحدهم؟ أكثر مدير يرقي ويوظف موظفين ومستقلين، يحتاج متابعة بخصوصها. | J22: أنس الأهدل | K22: 8.2291667 | L22: 6 | M22: 8.28 | N22: 6
B23: عبدالرحمن أبومالح | C23: 7.88 | D23: 7 | E23: 7.51 | F23: 5 | G23: ⬇ | H23: فتح باب التواصل أكثر بينه وبين الأقسام، بجلسات شهرية أو ربعية مع كل تنفيذي. يفعّل التواصل المباشر في المهام والمشاريع، ولا يسكت عن الخطأ من أول مرة، و بأسلوب مناسب. ترتيب الأوليات لدى الأقسام. أثره مهم، لكن أحيانًا غائب عن الفريق وموظفي ثمانية. ولو بكلمة طيبة أو تقدير. يحتاج تطوير للمهارات الإدارية، ياخذ دورة مثلًا؟
B24: أسيل باعبدالله - إنتاج | C24: 7.67 | D24: 7 | E24: 7.66 | F24: 2 | H24: - | J24: أسيل باعبدالله - إنتاج | K24: 7.67 | L24: 7 | M24: 7.66 | N24: 2
B25: فيصل الغامدي | C25: 8.09375 | D25: 6 | E25: 7.47 | F25: 4 | G25: ⬇ | H25: يمنع توظيف أي موظف/متدرب/مستقل جديد في فريقه، ما عدا مدير تطوير الأعمال باعتماد أبومالح والبراء. وإذا لم ينجح الموظف الجديد، فيتغير دور فيصل كقائد. | J25: فيصل الغامدي | K25: 8.09375 | L25: 6 | M25: 7.47 | N25: 4
B26: عمار الطحان | C26: - | E26: 7.47 | F26: 4 | H26: يحتاج مراجعة لإدارته للفريق. حول تقييمات فريقه والمدير، فهو شديد عليهم شوي، ولكن هذا الشيء طبيعي. | J26: عمار الطحان | K26: - | M26: 7.47 | N26: 4
B27: عبدالله الغامدي | C27: - | E27: 7.46 | F27: 4 | H27: يمنع توظيف أي موظف/متدرب/مستقل جديد، إلا بعد تطوير إدارته للفريق الحالي وارتفاع معدل التقييم، وحتى يعتمد على قراراته بدون تأثير وتدخل دائم من فيصل. | J27: عبدالله الغامدي | K27: - | M27: 7.46 | N27: 4
B28: محمد هاني | C28: 7.71875 | D28: 4 | E28: 7.34 | F28: 7 | G28: ⬇ | H28: يمنع توظيف أي موظف/متدرب/مستقل جديد، إلا بعد تطوير إدارته للفريق الحالي وارتفاع معدل التقييم، خاصة فيما يتعلق بأسلوبه وتعامله السلبي مع الفريق مما أثر نفسيًا على فريقه. | J28: محمد هاني | K28: 7.71875 | L28: 4 | M28: 7.34 | N28: 7
B29: أسيل باعبدالله - كامل | C29: 7.29375 | D29: 10 | E29: 7.19 | F29: 4 | G29: ⬇ | H29: تحتاج توظف نائب أو مدير معها + مساعد، وتغيير الهيكلة بحسب تقييمات القادة، وتركز أكثر على الفريق الحالي وتوزيع أدوارهم قبل فتح باب التوظيف. تحتاج تفعّل التواصل الداخلي في الفريق، وتعيد ترتيب خطة وآلية الإنتاج، فيه مشاكل عديدة ما أنلحت إلى الآن. رائعة ولكن تحتاج تتفرغ للصورة الكبيرة ومستقبل الإنتاج. | J29: أسيل باعبدالله - كامل | K29: 7.29375 | L29: 10 | M29: 7.19 | N29: 4
B30: نواف قوارش | C30: - | E30: 7.17 | F30: 5 | H30: هل ينفع يكون قائد؟ أو يبقى في المسار الفردي ونعين مدير آخر؟ | J30: نواف قوارش | K30: - | M30: 7.17 | N30: 5
B31: أسيل باعبدالله - تسويق | C31: 6.35 | D31: 3 | E31: 6.66 | F31: 2 | H31: - | J31: أسيل باعبدالله - تسويق | K31: 6.35 | L31: 3 | M31: 6.66 | N31: 2
B32: ميسم المنيع | C32: 8.5 | D32: 7 | E32: 5.22 | F32: 7 | G32: ⬇⬇ | H32: ميسم كان تقييمها دائمًا خضر، لكن من رمضان ويبدوا أنها تمر بحالة شخصية. يحتاج تقليص بعض من فريقها وانتقالهم إلى وهاب حتى تركز على فريقها والعمليات أكثر . المشكلة الأساسية أنها لا تشعر بأن اللي يحصل حاليًا مشكلة، وهذا خطأ بحد ذاته. لازم القائد يكون مسؤول وواعي بالمشاكل ويبادر في حلها. | J32: ميسم المنيع | K32: 8.5 | L32: 7 | M32: 5.22 | N32: 7
B35: 0-60 | C35: 60-70 | D35: 70-80 | E35: 80-90 | F35: 90-100
F36: من الأعلى للأقل⬇
B37: الأسئلة | E37: أغسطس 2024 | F37: أبريل 2025 | G37: التغيير مقارنة | J37: الأسئلة | M37: أغسطس 2024 | N37: أبريل 2025
B38: مُديري يقدم يد العون والمشورة في العمل متى ما طلبت منه. | E38: 9.1609195 | F38: 8.9228451 | G38: ⬇ | J38: مُديري فعّال في توصيل المعلومة والأفكار وإيضاح المهام. | M38: 8.2528736 | N38: 7.9879747
B39: مُديري يشجع ويدعم التفكير الإبداعي والأفكار المختلفة. | E39: 8.6117647 | F39: 8.8120879 | G39: ⬆ | J39: مُديري لديه وعي ذاتي وذكاء عاطفي ويتفهم مشاعر الفريق. | M39: 8.4352941 | N39: 8.0343882
B40: مُديري يُمكّن ويحفّز استقلاليتي، وأشعر بثقته العالية بالفريق. | E40: 8.6321839 | F40: 8.4773056 | G40: ⬇ | J40: مُديري يؤثر في معنويات الفريق ويحفزني باستمرار. | M40: 7.9655172 | N40: 7.6808921
B41: مُديري يتخذ قرارات صائبة تصب في مصلحة العمل والفريق. | E41: 8.5172414 | F41: 8.3253767 | G41: ⬇ | J41: مُديري يبني ويضع أهداف طموحة وواقعية للقسم والفريق. | M41: 8.0114943 | N41: 7.6705847
B42: مُديري يحسن في تفويض المهام ومشاركتنا المسؤوليات. | E42: 8.4767442 | F42: 8.2089512 | G42: ⬇ | J42: مُديري يتخذ قرارات صائبة تصب في مصلحة العمل والفريق. | M42: 8.5172414 | N42: 8.3253767
B43: مُديري لديه وعي ذاتي وذكاء عاطفي ويتفهم مشاعر الفريق. | E43: 8.4352941 | F43: 8.0343882 | G43: ⬇ | J43: مُديري يحدد الأولويات، ويعيد ترتيب موارد الفريق بانتظام. | M43: 7.9885057 | N43: 7.5527426
B44: مُديري فعّال في توصيل المعلومة والأفكار وإيضاح المهام. | E44: 8.2528736 | F44: 7.9879747 | G44: ⬇ | J44: مُديري يحسن في تفويض المهام ومشاركتنا المسؤوليات. | M44: 8.4767442 | N44: 8.2089512
...

Sheet ملخص 2025
D2: متوسط تقييم القادة | E2: 7.91
D3: عدد التقييمات | E3: 85 | G3: عدد المجاملين | H3: 5
A4: عدد المدراء | B4: =IFERROR(__xludf.DUMMYFUNCTION("COUNTUNIQUE('بعد تعديل المجاملين - أغسطس 202'!E:E)"),26.0) -> 26 | D4: عدد المدراء | E4: 20
A5: متوسط الشركة | B5: ='بعد تعديل المجاملين - أغسطس 202'!AF99 -> 8.0605469
E6: من الأعلى للأقل⬇ | J6: من الأعلى للأقل⬇ | N6: من الأعلى للأقل⬇
A7: إسم المدير | B7: متوسط التقييم | C7: عدد المُقيمين | D7: إسم المدير | E7: متوسط التقييم (بعد تعديل المجاملين) | F7: المجاملين | G7: عدد المُقيمين | I7: الأسئلة | J7: متوسط التقييم | L7: المستائين طبيعي إما يستقيلوا أو ينفصلوا أو يتغير دورهم/مديرهم أو خطة تطوير
A8: {=UNIQUE('تقييم القادة مايو 2025 - معتمد'!E3:E100)} -> أسيل باعبدالله | B8: =AVERAGEIF('تقييم القادة مايو 2025 - معتمد'!E$2:E$100,A8,'تقييم القادة مايو 2025 - معتمد'!AF$2:AF$100) -> 7.1875 | D8: وهاب محمد | E8: 9.33 | G8: 3 | I8: مُديري يقدم يد العون والمشورة في العمل متى ما طلبت منه. | J8: 8.9228451 | L8: الموظف | M8: المدير | N8: التقييم
